<?xml version="1.0"?>
<robot name="simple_3dof_arm">
  <link name="base_link">
    <visual>
      <geometry>
        <cylinder length="0.1" radius="0.1"/>
      </geometry>
      <material name="gray">
        <color rgba="0.5 0.5 0.5 1"/>
      </material>
    </visual>
    <collision>
      <geometry>
        <cylinder length="0.1" radius="0.1"/>
      </geometry>
    </collision>
    <inertial>
      <mass value="10"/>
      <inertia ixx="1.0" ixy="0.0" ixz="0.0" iyy="1.0" iyz="0.0" izz="1.0"/>
    </inertial>
  </link>

  <link name="link1">
    <visual>
      <geometry>
        <box size="0.1 0.1 0.5"/>
      </geometry>
      <origin xyz="0 0 0.25" rpy="0 0 0"/>
      <material name="red">
        <color rgba="1 0 0 1"/>
      </material>
    </visual>
    <collision>
      <geometry>
        <box size="0.1 0.1 0.5"/>
      </geometry>
      <origin xyz="0 0 0.25" rpy="0 0 0"/>
    </collision>
    <inertial>
      <mass value="1"/>
      <inertia ixx="0.1" ixy="0.0" ixz="0.0" iyy="0.1" iyz="0.0" izz="0.1"/>
    </inertial>
  </link>

  <joint name="joint1" type="revolute">
    <parent link="base_link"/>
    <child link="link1"/>
    <origin xyz="0 0 0.05" rpy="0 0 0"/>
    <axis xyz="0 0 1"/>
    <limit lower="-3.14" upper="3.14" effort="100" velocity="3.0"/>
  </joint>

  <link name="link2">
    <visual>
      <geometry>
        <box size="0.1 0.1 0.5"/>
      </geometry>
      <origin xyz="0 0 0.25" rpy="0 0 0"/>
      <material name="green">
        <color rgba="0 1 0 1"/>
      </material>
    </visual>
    <collision>
      <geometry>
        <box size="0.1 0.1 0.5"/>
      </geometry>
      <origin xyz="0 0 0.25" rpy="0 0 0"/>
    </collision>
    <inertial>
      <mass value="1"/>
      <inertia ixx="0.1" ixy="0.0" ixz="0.0" iyy="0.1" iyz="0.0" izz="0.1"/>
    </inertial>
  </link>

  <joint name="joint2" type="revolute">
    <parent link="link1"/>
    <child link="link2"/>
    <origin xyz="0 0 0.5" rpy="0 0 0"/>
    <axis xyz="0 1 0"/>
    <limit lower="-2.5" upper="2.5" effort="100" velocity="3.0"/>
  </joint>

  <link name="link3">
    <visual>
      <geometry>
        <box size="0.1 0.1 0.4"/>
      </geometry>
      <origin xyz="0 0 0.2" rpy="0 0 0"/>
      <material name="blue">
        <color rgba="0 0 1 1"/>
      </material>
    </visual>
    <collision>
      <geometry>
        <box size="0.1 0.1 0.4"/>
      </geometry>
      <origin xyz="0 0 0.2" rpy="0 0 0"/>
    </collision>
    <inertial>
      <mass value="1"/>
      <inertia ixx="0.1" ixy="0.0" ixz="0.0" iyy="0.1" iyz="0.0" izz="0.1"/>
    </inertial>
  </link>

  <joint name="joint3" type="revolute">
    <parent link="link2"/>
    <child link="link3"/>
    <origin xyz="0 0 0.5" rpy="0 0 0"/>
    <axis xyz="0 1 0"/>
    <limit lower="-2.5" upper="2.5" effort="100" velocity="3.0"/>
  </joint>

  <link name="end_effector">
    <inertial>
      <mass value="0.5"/>
      <inertia ixx="0.01" ixy="0.0" ixz="0.0" iyy="0.01" iyz="0.0" izz="0.01"/>
    </inertial>

    <visual>
      <geometry>
        <box size="0.06 0.06 0.01"/>
      </geometry>
      <origin xyz="0 0 0" rpy="0 0 0"/>
      <material name="white">
        <color rgba="1 1 1 1"/>
      </material>
    </visual>
    <collision>
      <geometry>
        <box size="0.06 0.06 0.01"/>
      </geometry>
      <origin xyz="0 0 0" rpy="0 0 0"/>
    </collision>

    <visual>
      <geometry>
        <box size="0.1 0.01 0.08"/>
      </geometry>
      <origin xyz="0 0.035 0.035" rpy="-0.52 0 0"/> 
      <material name="white"/>
    </visual>
    <collision>
      <geometry>
        <box size="0.1 0.01 0.08"/>
      </geometry>
      <origin xyz="0 0.035 0.035" rpy="-0.52 0 0"/>
    </collision>

    <visual>
      <geometry>
        <box size="0.1 0.01 0.08"/>
      </geometry>
      <origin xyz="0 -0.035 0.035" rpy="0.52 0 0"/>
      <material name="white"/>
    </visual>
    <collision>
      <geometry>
        <box size="0.1 0.01 0.08"/>
      </geometry>
      <origin xyz="0 -0.035 0.035" rpy="0.52 0 0"/>
    </collision>

    <visual>
      <geometry>
        <box size="0.01 0.08 0.08"/>
      </geometry>
      <origin xyz="0.035 0 0.035" rpy="0 0.52 0"/>
      <material name="white"/>
    </visual>
    <collision>
      <geometry>
        <box size="0.01 0.08 0.08"/>
      </geometry>
      <origin xyz="0.035 0 0.035" rpy="0 0.52 0"/>
    </collision>

    <visual>
      <geometry>
        <box size="0.01 0.08 0.08"/>
      </geometry>
      <origin xyz="-0.035 0 0.035" rpy="0 -0.52 0"/>
      <material name="white"/>
    </visual>
    <collision>
      <geometry>
        <box size="0.01 0.08 0.08"/>
      </geometry>
      <origin xyz="-0.035 0 0.035" rpy="0 -0.52 0"/>
    </collision>
  </link>

  <joint name="ee_joint" type="fixed">
    <parent link="link3"/>
    <child link="end_effector"/>
    <origin xyz="0 0 0.4" rpy="0 0 0"/>
  </joint>

</robot>