<?xml version="1.0"?>
<robot name="quadruped_ganimata_robot">

  <material name="blue">
    <color rgba="0 1 0.8 1"/>
  </material>
  <material name="white">
    <color rgba="1 1 1 1"/>
  </material>

  <link name="base_footprint"/>

  <joint name="base_joint" type="fixed">
    <parent link="base_footprint"/>
    <child link="base_link"/>
    <origin xyz="0 0 0" rpy="0 0 0"/>
  </joint>

  <link name="base_link">
    <visual>
      <origin xyz="0 0 0" rpy="0 0 0"/>
      <geometry>
        <cylinder length="0.02" radius="0.2"/>
      </geometry>
      <material name="blue"/>
    </visual>
    <collision>
      <origin xyz="0 0 0" rpy="0 0 0"/>
      <geometry>
        <cylinder length="0.02" radius="0.2"/>
      </geometry>
    </collision>
    <inertial>
      <mass value="2.0"/>
      <inertia ixx="0.02" ixy="0.0" ixz="0.0" iyy="0.02" iyz="0.0" izz="0.04"/>
    </inertial>
  </link>

  <!-- Leg 1 (Front Left) -->
  <joint name="leg1_hip_joint" type="revolute">
    <parent link="base_link"/>
    <child link="leg1_upper"/>
    <origin xyz="0.2 0.15 0" rpy="0 -1.57 0"/>
    <axis xyz="0 1 0"/> 
    <limit lower="-1.57" upper="1.57" effort="10.0" velocity="10.0"/>
  </joint>

  <link name="leg1_upper">
    <visual>
      <origin xyz="0 0 -0.1" rpy="0 0 0"/>
      <geometry>
        <cylinder length="0.2" radius="0.03"/>
      </geometry>
      <material name="white"/>
    </visual>
    <collision>
      <origin xyz="0 0 -0.1" rpy="0 0 0"/>
      <geometry>
        <cylinder length="0.2" radius="0.03"/>
      </geometry>
    </collision>
    <inertial>
      <origin xyz="0 0 -0.1" rpy="0 0 0"/>
      <mass value="5.0"/>
      <inertia ixx="0.0386" ixy="0.0" ixz="0.0" iyy="0.0386" iyz="0.0" izz="0.00225"/>
    </inertial>
  </link>

  <joint name="leg1_knee_joint" type="revolute">
    <parent link="leg1_upper"/>
    <child link="leg1_lower"/>
    <origin xyz="0 0 -0.2" rpy="0 1.57 0"/>
    <axis xyz="0 1 0"/>
    <limit lower="-1.57" upper="1.57" effort="10.0" velocity="10.0"/>
  </joint>

  <link name="leg1_lower">
    <visual>
      <origin xyz="0 0 -0.1" rpy="0 0 0"/>
      <geometry>
        <cylinder length="0.2" radius="0.03"/>
      </geometry>
      <material name="white"/>
    </visual>
    <visual>
      <origin xyz="0 0 -0.2" rpy="0 0 0"/>
      <geometry>
        <sphere radius="0.03"/>
      </geometry>
      <material name="white"/>
    </visual>
    <collision>
      <origin xyz="0 0 -0.1" rpy="0 0 0"/>
      <geometry>
        <cylinder length="0.2" radius="0.03"/>
      </geometry>
    </collision>
    <collision>
      <origin xyz="0 0 -0.2" rpy="0 0 0"/>
      <geometry>
        <sphere radius="0.03"/>
      </geometry>
    </collision>
    <inertial>
      <origin xyz="0 0 -0.1" rpy="0 0 0"/>
      <mass value="5.0"/>
      <inertia ixx="0.0386" ixy="0.0" ixz="0.0" iyy="0.0386" iyz="0.0" izz="0.00225"/>
    </inertial>
  </link>

  <!-- Leg 2 (Front Right) -->
  <joint name="leg2_hip_joint" type="revolute">
    <parent link="base_link"/>
    <child link="leg2_upper"/>
    <origin xyz="0.2 -0.15 0" rpy="0 -1.57 0"/>
    <axis xyz="0 1 0"/>
    <limit lower="-1.57" upper="1.57" effort="10.0" velocity="10.0"/>
  </joint>

  <link name="leg2_upper">
    <visual>
      <origin xyz="0 0 -0.1" rpy="0 0 0"/>
      <geometry>
        <cylinder length="0.2" radius="0.03"/>
      </geometry>
      <material name="white"/>
    </visual>
    <collision>
      <origin xyz="0 0 -0.1" rpy="0 0 0"/>
      <geometry>
        <cylinder length="0.2" radius="0.03"/>
      </geometry>
    </collision>
    <inertial>
      <origin xyz="0 0 -0.1" rpy="0 0 0"/>
      <mass value="5.0"/>
      <inertia ixx="0.0386" ixy="0.0" ixz="0.0" iyy="0.0386" iyz="0.0" izz="0.00225"/>
    </inertial>
  </link>

  <joint name="leg2_knee_joint" type="revolute">
    <parent link="leg2_upper"/>
    <child link="leg2_lower"/>
    <origin xyz="0 0 -0.2" rpy="0 1.57 0"/>
    <axis xyz="0 1 0"/>
    <limit lower="-1.57" upper="1.57" effort="10.0" velocity="10.0"/>
  </joint>

  <link name="leg2_lower">
    <visual>
      <origin xyz="0 0 -0.1" rpy="0 0 0"/>
      <geometry>
        <cylinder length="0.2" radius="0.03"/>
      </geometry>
      <material name="white"/>
    </visual>
    <visual>
      <origin xyz="0 0 -0.2" rpy="0 0 0"/>
      <geometry>
        <sphere radius="0.03"/>
      </geometry>
      <material name="white"/>
    </visual>
    <collision>
      <origin xyz="0 0 -0.1" rpy="0 0 0"/>
      <geometry>
        <cylinder length="0.2" radius="0.03"/>
      </geometry>
    </collision>
    <collision>
      <origin xyz="0 0 -0.2" rpy="0 0 0"/>
      <geometry>
        <sphere radius="0.03"/>
      </geometry>
    </collision>
    <inertial>
      <origin xyz="0 0 -0.1" rpy="0 0 0"/>
      <mass value="5.0"/>
      <inertia ixx="0.0386" ixy="0.0" ixz="0.0" iyy="0.0386" iyz="0.0" izz="0.00225"/>
    </inertial>
  </link>

  <!-- Leg 3 (Rear Left) -->
  <joint name="leg3_hip_joint" type="revolute">
    <parent link="base_link"/>
    <child link="leg3_upper"/>
    <origin xyz="-0.2 0.15 0" rpy="0 1.57 0"/>
    <axis xyz="0 1 0"/>
    <limit lower="-1.57" upper="1.57" effort="10.0" velocity="10.0"/>
  </joint>

  <link name="leg3_upper">
    <visual>
      <origin xyz="0 0 -0.1" rpy="0 0 0"/>
      <geometry>
        <cylinder length="0.2" radius="0.03"/>
      </geometry>
      <material name="white"/>
    </visual>
    <collision>
      <origin xyz="0 0 -0.1" rpy="0 0 0"/>
      <geometry>
        <cylinder length="0.2" radius="0.03"/>
      </geometry>
    </collision>
    <inertial>
      <origin xyz="0 0 -0.1" rpy="0 0 0"/>
      <mass value="5.0"/>
      <inertia ixx="0.0386" ixy="0.0" ixz="0.0" iyy="0.0386" iyz="0.0" izz="0.00225"/>
    </inertial>
  </link>

  <joint name="leg3_knee_joint" type="revolute">
    <parent link="leg3_upper"/>
    <child link="leg3_lower"/>
    <origin xyz="0 0 -0.2" rpy="0 -1.57 0"/>
    <axis xyz="0 1 0"/>
    <limit lower="-1.57" upper="1.57" effort="10.0" velocity="10.0"/>
  </joint>

  <link name="leg3_lower">
    <visual>
      <origin xyz="0 0 -0.1" rpy="0 0 0"/>
      <geometry>
        <cylinder length="0.2" radius="0.03"/>
      </geometry>
      <material name="white"/>
    </visual>
    <visual>
      <origin xyz="0 0 -0.2" rpy="0 0 0"/>
      <geometry>
        <sphere radius="0.03"/>
      </geometry>
      <material name="white"/>
    </visual>
    <collision>
      <origin xyz="0 0 -0.1" rpy="0 0 0"/>
      <geometry>
        <cylinder length="0.2" radius="0.03"/>
      </geometry>
    </collision>
    <collision>
      <origin xyz="0 0 -0.2" rpy="0 0 0"/>
      <geometry>
        <sphere radius="0.03"/>
      </geometry>
    </collision>
    <inertial>
      <origin xyz="0 0 -0.1" rpy="0 0 0"/>
      <mass value="5.0"/>
      <inertia ixx="0.0386" ixy="0.0" ixz="0.0" iyy="0.0386" iyz="0.0" izz="0.00225"/>
    </inertial>
  </link>

  <!-- Leg 4 (Rear Right) -->
  <joint name="leg4_hip_joint" type="revolute">
    <parent link="base_link"/>
    <child link="leg4_upper"/>
    <origin xyz="-0.2 -0.15 0" rpy="0 1.57 0"/>
    <axis xyz="0 1 0"/>
    <limit lower="-1.57" upper="1.57" effort="10.0" velocity="10.0"/>
  </joint>

  <link name="leg4_upper">
    <visual>
      <origin xyz="0 0 -0.1" rpy="0 0 0"/>
      <geometry>
        <cylinder length="0.2" radius="0.03"/>
      </geometry>
      <material name="white"/>
    </visual>
    <collision>
      <origin xyz="0 0 -0.1" rpy="0 0 0"/>
      <geometry>
        <cylinder length="0.2" radius="0.03"/>
      </geometry>
    </collision>
    <inertial>
      <origin xyz="0 0 -0.1" rpy="0 0 0"/>
      <mass value="5.0"/>
      <inertia ixx="0.0386" ixy="0.0" ixz="0.0" iyy="0.0386" iyz="0.0" izz="0.00225"/>
    </inertial>
  </link>

  <joint name="leg4_knee_joint" type="revolute">
    <parent link="leg4_upper"/>
    <child link="leg4_lower"/>
    <origin xyz="0 0 -0.2" rpy="0 -1.57 0"/>
    <axis xyz="0 1 0"/>
    <limit lower="-1.57" upper="1.57" effort="10.0" velocity="10.0"/>
  </joint>

  <link name="leg4_lower">
    <visual>
      <origin xyz="0 0 -0.1" rpy="0 0 0"/>
      <geometry>
        <cylinder length="0.2" radius="0.03"/>
      </geometry>
      <material name="white"/>
    </visual>
    <visual>
      <origin xyz="0 0 -0.2" rpy="0 0 0"/>
      <geometry>
        <sphere radius="0.03"/>
      </geometry>
      <material name="white"/>
    </visual>
    <collision>
      <origin xyz="0 0 -0.1" rpy="0 0 0"/>
      <geometry>
        <cylinder length="0.2" radius="0.03"/>
      </geometry>
    </collision>
    <collision>
      <origin xyz="0 0 -0.2" rpy="0 0 0"/>
      <geometry>
        <sphere radius="0.03"/>
      </geometry>
    </collision>
    <inertial>
      <origin xyz="0 0 -0.1" rpy="0 0 0"/>
      <mass value="5.0"/>
      <inertia ixx="0.0386" ixy="0.0" ixz="0.0" iyy="0.0386" iyz="0.0" izz="0.00225"/>
    </inertial>
  </link>

  <link name="leg4_lower">
    <visual>
      <origin xyz="0 0 -0.15" rpy="0 0 0"/>
      <geometry>
        <cylinder length="0.3" radius="0.03"/>
      </geometry>
      <material name="white"/>
    </visual>
    <visual>
      <origin xyz="0 0 -0.3" rpy="0 0 0"/>
      <geometry>
        <sphere radius="0.03"/>
      </geometry>
      <material name="white"/>
    </visual>
    <collision>
      <origin xyz="0 0 -0.15" rpy="0 0 0"/>
      <geometry>
        <cylinder length="0.3" radius="0.03"/>
      </geometry>
    </collision>
    <collision>
      <origin xyz="0 0 -0.3" rpy="0 0 0"/>
      <geometry>
        <sphere radius="0.03"/>
      </geometry>
    </collision>
    <inertial>
      <origin xyz="0 0 -0.15" rpy="0 0 0"/>
      <mass value="5.0"/>
      <inertia ixx="0.0386" ixy="0.0" ixz="0.0" iyy="0.0386" iyz="0.0" izz="0.00225"/>
    </inertial>
  </link>

</robot>